12/16/2020 11:10:03 AM - INFO - StartFlow  save_param: FlowName is 测试\录屏测试, FlowNum is 0, flag is: 1
12/16/2020 11:10:03 AM - INFO - StartFlow  save_param: FlowNum 0 流程二次或多次开启
12/16/2020 11:10:03 AM - INFO - StartFlow  save_param: FlowNum 0 已重新创建
12/16/2020 11:10:24 AM - WARNING - StartFlow post: FlowName : 测试\录屏测试 流程名称不正确
12/16/2020 11:11:57 AM - INFO - StartFlow  save_param: FlowName is 测试\录屏测试, FlowNum is 0, flag is: 1
12/16/2020 11:11:57 AM - INFO - StartFlow  save_param: FlowNum 0 流程二次或多次开启
12/16/2020 11:11:57 AM - WARNING - StartFlow post: FlowName : 测试\录屏测试 流程名称不正确
12/16/2020 11:15:22 AM - INFO - StartFlow  save_param: FlowName is 测试\录屏测试, FlowNum is 0, flag is: 1
12/16/2020 11:15:22 AM - INFO - StartFlow  save_param: FlowNum 0 流程二次或多次开启
12/16/2020 11:15:22 AM - WARNING - StartFlow post: FlowName : 测试\录屏测试 流程名称不正确
12/16/2020 12:02:35 PM - INFO - StartFlow  save_param: FlowName is 测试\录屏测试, FlowNum is 0, flag is: 1
12/16/2020 12:02:35 PM - INFO - StartFlow  save_param: FlowNum 0 流程二次或多次开启
12/16/2020 12:02:35 PM - WARNING - StartFlow post: FlowName : 测试\录屏测试 流程名称不正确
12/16/2020 12:02:59 PM - INFO - StartFlow  save_param: FlowName is 测试\录屏测试, FlowNum is 0, flag is: 1
12/16/2020 12:02:59 PM - INFO - StartFlow  save_param: FlowNum 0 流程二次或多次开启
12/16/2020 12:02:59 PM - INFO - StartFlow post: FlowName : 测试\录屏测试 流程执行成功
12/16/2020 14:55:43 PM - INFO - StartFlow  save_param: FlowName is TA-OTC数据导入, FlowNum is 621, flag is: 0
12/16/2020 14:55:43 PM - ERROR - Internal Server Error: /command/startflow
Traceback (most recent call last):
  File "C:\Users\zhubh\AppData\Local\Programs\Python\Python36\lib\site-packages\django\core\handlers\exception.py", line 35, in inner
    response = get_response(request)
  File "C:\Users\zhubh\AppData\Local\Programs\Python\Python36\lib\site-packages\django\core\handlers\base.py", line 128, in _get_response
    response = self.process_exception_by_middleware(e, request)
  File "C:\Users\zhubh\AppData\Local\Programs\Python\Python36\lib\site-packages\django\core\handlers\base.py", line 126, in _get_response
    response = wrapped_callback(request, *callback_args, **callback_kwargs)
  File "C:\Users\zhubh\AppData\Local\Programs\Python\Python36\lib\site-packages\django\views\generic\base.py", line 69, in view
    return self.dispatch(request, *args, **kwargs)
  File "C:\Users\zhubh\AppData\Local\Programs\Python\Python36\lib\site-packages\django\views\generic\base.py", line 89, in dispatch
    return handler(request, *args, **kwargs)
  File "D:\pyfile\github_files\hobby\RPA_web\RPA\rpa_command\views.py", line 172, in post
    result_save = self.save_param()
  File "D:\pyfile\github_files\hobby\RPA_web\RPA\rpa_command\views.py", line 152, in save_param
    if machine_status[0]['machine_status'] != '0':
  File "C:\Users\zhubh\AppData\Local\Programs\Python\Python36\lib\site-packages\django\db\models\query.py", line 307, in __getitem__
    return qs._result_cache[0]
IndexError: list index out of range
12/16/2020 14:58:19 PM - INFO - StartFlow  save_param: FlowName is TA-OTC数据导入, FlowNum is 621, flag is: 1
12/16/2020 14:58:19 PM - INFO - StartFlow  save_param: FlowNum 621 流程二次或多次开启
12/16/2020 14:58:19 PM - INFO - StartFlow  save_param: FlowNum 621 已重新创建
12/16/2020 14:58:19 PM - WARNING - StartFlow post: FlowName : TA-OTC数据导入 流程名称不正确
12/18/2020 14:40:50 PM - INFO - FlowResult post: 流程名：托管部\TA日清算\TA日初始化, 流程执行结果：窗口未获取到
12/18/2020 14:40:50 PM - INFO - FlowResult post: 流程名:托管部\TA日清算\TA日初始化, 流程执行失败，失败信息：窗口未获取到
12/18/2020 14:40:50 PM - DEBUG - Starting new HTTP connection (1): 10.32.132.27:80
12/18/2020 14:41:11 PM - DEBUG - FlowResult post: 回调API失败，失败信息：HTTPConnectionPool(host='10.32.132.27', port=80): Max retries exceeded with url: /vesta/vesta_rpa?method=callback (Caused by NewConnectionError('<urllib3.connection.HTTPConnection object at 0x00000226CE96F080>: Failed to establish a new connection: [WinError 10060] 由于连接方在一段时间后没有正确答复或连接的主机没有反应，连接尝试失败。',))
